Workbook

Sheet final_manifest
A1: decision_date | B1: year | C1: case_numbers | D1: decision_label | E1: decision_title | F1: source | G1: source_native_id | H1: source_record_id | I1: case_numbers_raw | J1: date_caseno_key | K1: date_caseno_source_key | L1: has_downloadable_url | M1: is_downloaded | N1: download_status | O1: source_urls | P1: download_urls | Q1: download_paths | R1: successful_download_paths | S1: source_manifest_file
A2: 23447 | B2: =YEAR(A2) -> 1964 | C2: 61 | D2: Negative Clearance | Negative Clearance Decision | E2: Grosfillex & Fillistorf | Grosfillex | Fillistorf | F2: andrea | com_legacy | G2: 1 | com_legacy_1964_line_14 | H2: andrea:1 | com_legacy:com_legacy_1964_line_14 | I2: 61 | IV/61 | J2: 1964/11/03/61 | K2: 1964/11/03/61/andrea | 1964/11/03/61/com_legacy | L2: TRUE | M2: TRUE | N2: reference_only | already_downloaded | O2: http://ec.europa.eu/competition/antitrust/closed/en/1964.html | P2: https://eur-lex.europa.eu/legal-content/EN/TXT/HTML/?uri=CELEX:31964D0233 | https://eur-lex.europa.eu/legal-content/EN/TXT/PDF/?uri=CELEX:31964D0233 | https://eur-lex.europa.eu/legal-content/DE/TXT/HTML/?uri=CELEX:31964D0233 | https://eur-lex.europa.eu/legal-content/DE/TXT/PDF/?uri=CELEX:31964D0233 | http://ec.europa.eu/competition/search.html | http://ec.europa.eu/competition/antitrust/closed/en/1964.html#top | Q2: /home/edik/projects/eccjeu/data/raw/com_legacy/files/html/31964D0233_DE.html | /home/edik/projects/eccjeu/data/raw/com_legacy/files/pdfs/31964D0233_DE.pdf | /home/edik/projects/eccjeu/data/raw/com_legacy/files/html/search.html | /home/edik/projects/eccjeu/data/raw/com_legacy/files/html/1964.html | R2: /home/edik/projects/eccjeu/data/raw/com_legacy/files/html/31964D0233_DE.html | /home/edik/projects/eccjeu/data/raw/com_legacy/files/pdfs/31964D0233_DE.pdf | /home/edik/projects/eccjeu/data/raw/com_legacy/files/html/search.html | /home/edik/projects/eccjeu/data/raw/com_legacy/files/html/1964.html | S2: /home/edik/projects/eccjeu/input/andrea_input.csv | /home/edik/projects/eccjeu/output/com_legacy/download_case_manifest.csv
A3: 23529 | B3: =YEAR(A3) -> 1964 | C3: 12868 | D3: Negative Clearance | Negative Clearance Decision | E3: Bendix & Meertens and Straet | Bendix | Mertens and Straat | F3: andrea | com_legacy | G3: 2 | com_legacy_1964_line_11 | H3: andrea:2 | com_legacy:com_legacy_1964_line_11 | I3: 12868 | IV/12868 | J3: 1964/01/06/12868 | K3: 1964/01/06/12868/andrea | 1964/01/06/12868/com_legacy | L3: TRUE | M3: TRUE | N3: reference_only | already_downloaded | O3: http://ec.europa.eu/competition/antitrust/closed/en/1964.html | P3: https://eur-lex.europa.eu/legal-content/EN/TXT/HTML/?uri=CELEX:31964D0344 | https://eur-lex.europa.eu/legal-content/EN/TXT/PDF/?uri=CELEX:31964D0344 | https://eur-lex.europa.eu/legal-content/DE/TXT/HTML/?uri=CELEX:31964D0344 | https://eur-lex.europa.eu/legal-content/DE/TXT/PDF/?uri=CELEX:31964D0344 | Q3: /home/edik/projects/eccjeu/data/raw/com_legacy/files/html/31964D0344_DE.html | /home/edik/projects/eccjeu/data/raw/com_legacy/files/pdfs/31964D0344_DE.pdf | R3: /home/edik/projects/eccjeu/data/raw/com_legacy/files/html/31964D0344_DE.html | /home/edik/projects/eccjeu/data/raw/com_legacy/files/pdfs/31964D0344_DE.pdf | S3: /home/edik/projects/eccjeu/input/andrea_input.csv | /home/edik/projects/eccjeu/output/com_legacy/download_case_manifest.csv
A4: 23588 | B4: =YEAR(A4) -> 1964 | C4: 95 | D4: Negative Clearance | not_exclusion_candidate | Negative Clearance Decision | E4: Nicholas Frères & Vitapro | Nicholas Freres/Vitapro | Nicholas Freres | Vitapro | F4: andrea | com_db_comp | com_legacy | G4: 3 | 1801 | com_legacy_1964_line_8 | H4: andrea:3 | com_db_comp:1801 | com_legacy:com_legacy_1964_line_8 | I4: 95 | IV/95 | J4: 1964/07/30/95 | K4: 1964/07/30/95/andrea | 1964/07/30/95/com_db_comp | 1964/07/30/95/com_legacy | L4: TRUE | M4: TRUE | N4: reference_only | already_downloaded | O4: https://db-comp.eu/document_1801.download | http://ec.europa.eu/competition/antitrust/closed/en/1964.html | P4: https://db-comp.eu/document_1801.download | https://eur-lex.europa.eu/legal-content/EN/TXT/HTML/?uri=CELEX:31964D0502 | https://eur-lex.europa.eu/legal-content/EN/TXT/PDF/?uri=CELEX:31964D0502 | https://eur-lex.europa.eu/legal-content/DE/TXT/HTML/?uri=CELEX:31964D0502 | https://eur-lex.europa.eu/legal-content/DE/TXT/PDF/?uri=CELEX:31964D0502 | Q4: /home/edik/projects/eccjeu/data/raw/com_db_comp/files/00093-EMO-_Dec-1988_.pdf | /home/edik/projects/eccjeu/data/raw/com_legacy/files/html/31964D0502_DE.html | /home/edik/projects/eccjeu/data/raw/com_legacy/files/pdfs/31964D0502_DE.pdf | R4: /home/edik/projects/eccjeu/data/raw/com_db_comp/files/00093-EMO-_Dec-1988_.pdf | /home/edik/projects/eccjeu/data/raw/com_legacy/files/html/31964D0502_DE.html | /home/edik/projects/eccjeu/data/raw/com_legacy/files/pdfs/31964D0502_DE.pdf | S4: /home/edik/projects/eccjeu/input/andrea_input.csv | /home/edik/projects/eccjeu/output/com_db_comp/db_comp_metadata_manifest.csv | /home/edik/projects/eccjeu/output/com_legacy/download_case_manifest.csv
A5: 23643 | B5: =YEAR(A5) -> 1964 | C5: 3344; 4 | D5: Infringement | Prohibition Decision | E5: Grundig-Consten | F5: andrea | com_legacy | G5: 4 | com_legacy_1964_line_5 | H5: andrea:4 | com_legacy:com_legacy_1964_line_5 | I5: 3344 | IV/3344 | IV/4 | J5: 1964/09/23/3344 | 1964/09/23/4/3344 | K5: 1964/09/23/3344/andrea | 1964/09/23/4/3344/com_legacy | L5: TRUE | M5: TRUE | N5: reference_only | already_downloaded | O5: http://ec.europa.eu/competition/antitrust/closed/en/1964.html | P5: https://eur-lex.europa.eu/legal-content/EN/TXT/HTML/?uri=CELEX:31964D0566 | https://eur-lex.europa.eu/legal-content/EN/TXT/PDF/?uri=CELEX:31964D0566 | https://eur-lex.europa.eu/legal-content/DE/TXT/HTML/?uri=CELEX:31964D0566 | https://eur-lex.europa.eu/legal-content/DE/TXT/PDF/?uri=CELEX:31964D0566 | Q5: /home/edik/projects/eccjeu/data/raw/com_legacy/files/html/31964D0566_DE.html | /home/edik/projects/eccjeu/data/raw/com_legacy/files/pdfs/31964D0566_DE.pdf | R5: /home/edik/projects/eccjeu/data/raw/com_legacy/files/html/31964D0566_DE.html | /home/edik/projects/eccjeu/data/raw/com_legacy/files/pdfs/31964D0566_DE.pdf | S5: /home/edik/projects/eccjeu/input/andrea_input.csv | /home/edik/projects/eccjeu/output/com_legacy/download_case_manifest.csv
A6: 23672 | B6: =YEAR(A6) -> 1964 | C6: 71 | D6: Negative Clearance | Negative Clearance Decision | E6: Deca | F6: andrea | com_legacy | G6: 5 | com_legacy_1964_line_2 | H6: andrea:5 | com_legacy:com_legacy_1964_line_2 | I6: 71 | IV/71 | J6: 1964/10/22/71 | K6: 1964/10/22/71/andrea | 1964/10/22/71/com_legacy | L6: TRUE | M6: TRUE | N6: reference_only | already_downloaded | O6: http://ec.europa.eu/competition/antitrust/closed/en/1964.html | P6: https://eur-lex.europa.eu/legal-content/EN/TXT/HTML/?uri=CELEX:31964D0599 | https://eur-lex.europa.eu/legal-content/EN/TXT/PDF/?uri=CELEX:31964D0599 | https://eur-lex.europa.eu/legal-content/DE/TXT/HTML/?uri=CELEX:31964D0599 | https://eur-lex.europa.eu/legal-content/DE/TXT/PDF/?uri=CELEX:31964D0599 | Q6: /home/edik/projects/eccjeu/data/raw/com_legacy/files/html/31964D0599_DE.html | /home/edik/projects/eccjeu/data/raw/com_legacy/files/pdfs/31964D0599_DE.pdf | R6: /home/edik/projects/eccjeu/data/raw/com_legacy/files/html/31964D0599_DE.html | /home/edik/projects/eccjeu/data/raw/com_legacy/files/pdfs/31964D0599_DE.pdf | S6: /home/edik/projects/eccjeu/input/andrea_input.csv | /home/edik/projects/eccjeu/output/com_legacy/download_case_manifest.csv
A7: 23931 | B7: =YEAR(A7) -> 1965 | C7: 3036 | D7: Exemption | not_exclusion_candidate | Exemption Decision | E7: Dru-Blondel | D.R.U./Blondel | F7: andrea | com_db_comp | com_legacy | G7: 6 | 1754 | com_legacy_1965_line_8 | H7: andrea:6 | com_db_comp:1754 | com_legacy:com_legacy_1965_line_8 | I7: 3036 | IV/3036 | J7: 1965/08/07/3036 | K7: 1965/08/07/3036/andrea | 1965/08/07/3036/com_db_comp | 1965/08/07/3036/com_legacy | L7: TRUE | M7: TRUE | N7: reference_only | already_downloaded | O7: https://db-comp.eu/document_1754.download | http://ec.europa.eu/competition/antitrust/closed/en/1965.html | P7: https://db-comp.eu/document_1754.download | https://eur-lex.europa.eu/legal-content/EN/TXT/HTML/?uri=CELEX:31965D0366 | https://eur-lex.europa.eu/legal-content/EN/TXT/PDF/?uri=CELEX:31965D0366 | https://eur-lex.europa.eu/legal-content/DE/TXT/HTML/?uri=CELEX:31965D0366 | https://eur-lex.europa.eu/legal-content/DE/TXT/PDF/?uri=CELEX:31965D0366 | http://ec.europa.eu/competition/search.html | http://ec.europa.eu/competition/antitrust/closed/en/1965.html#top | Q7: /home/edik/projects/eccjeu/data/raw/com_db_comp/files/3036-D.R.U.-Blondel-_July-1965_.pdf | /home/edik/projects/eccjeu/data/raw/com_legacy/files/html/31965D0366_DE.html | /home/edik/projects/eccjeu/data/raw/com_legacy/files/pdfs/31965D0366_DE.pdf | /home/edik/projects/eccjeu/data/raw/com_legacy/files/html/search.html | /home/edik/projects/eccjeu/data/raw/com_legacy/files/html/1965.html | R7: /home/edik/projects/eccjeu/data/raw/com_db_comp/files/3036-D.R.U.-Blondel-_July-1965_.pdf | /home/edik/projects/eccjeu/data/raw/com_legacy/files/html/31965D0366_DE.html | /home/edik/projects/eccjeu/data/raw/com_legacy/files/pdfs/31965D0366_DE.pdf | /home/edik/projects/eccjeu/data/raw/com_legacy/files/html/search.html | /home/edik/projects/eccjeu/data/raw/com_legacy/files/html/1965.html | S7: /home/edik/projects/eccjeu/input/andrea_input.csv | /home/edik/projects/eccjeu/output/com_db_comp/db_comp_metadata_manifest.csv | /home/edik/projects/eccjeu/output/com_legacy/download_case_manifest.csv
A8: 24002 | B8: =YEAR(A8) -> 1965 | C8: 2702 | D8: Exemption | Exemption Decision | E8: Hummel-Isbecque | Hummel - Isbecque | F8: andrea | com_legacy | G8: 7 | com_legacy_1965_line_5 | H8: andrea:7 | com_legacy:com_legacy_1965_line_5 | I8: 2702 | IV/2702 | J8: 1965/09/17/2702 | K8: 1965/09/17/2702/andrea | 1965/09/17/2702/com_legacy | L8: TRUE | M8: TRUE | N8: reference_only | already_downloaded | O8: http://ec.europa.eu/competition/antitrust/closed/en/1965.html | P8: https://eur-lex.europa.eu/legal-content/EN/TXT/HTML/?uri=CELEX:31965D0426 | https://eur-lex.europa.eu/legal-content/EN/TXT/PDF/?uri=CELEX:31965D0426 | https://eur-lex.europa.eu/legal-content/DE/TXT/HTML/?uri=CELEX:31965D0426 | https://eur-lex.europa.eu/legal-content/DE/TXT/PDF/?uri=CELEX:31965D0426 | Q8: /home/edik/projects/eccjeu/data/raw/com_legacy/files/html/31965D0426_DE.html | /home/edik/projects/eccjeu/data/raw/com_legacy/files/pdfs/31965D0426_DE.pdf | R8: /home/edik/projects/eccjeu/data/raw/com_legacy/files/html/31965D0426_DE.html | /home/edik/projects/eccjeu/data/raw/com_legacy/files/pdfs/31965D0426_DE.pdf | S8: /home/edik/projects/eccjeu/input/andrea_input.csv | /home/edik/projects/eccjeu/output/com_legacy/download_case_manifest.csv
A9: 24093 | B9: =YEAR(A9) -> 1965 | C9: 22491 | D9: Exemption | Exemption Decision | E9: Maison Jallatte | Maison Jalatte | F9: andrea | com_legacy | G9: 8 | com_legacy_1965_line_2 | H9: andrea:8 | com_legacy:com_legacy_1965_line_2 | I9: 22491 | IV/22491 | J9: 1965/12/17/22491 | K9: 1965/12/17/22491/andrea | 1965/12/17/22491/com_legacy | L9: TRUE | M9: TRUE | N9: reference_only | already_downloaded | O9: http://ec.europa.eu/competition/antitrust/closed/en/1965.html | P9: https://eur-lex.europa.eu/legal-content/EN/TXT/HTML/?uri=CELEX:31966D0005 | https://eur-lex.europa.eu/legal-content/EN/TXT/PDF/?uri=CELEX:31966D0005 | https://eur-lex.europa.eu/legal-content/DE/TXT/HTML/?uri=CELEX:31966D0005 | https://eur-lex.europa.eu/legal-content/DE/TXT/PDF/?uri=CELEX:31966D0005 | Q9: /home/edik/projects/eccjeu/data/raw/com_legacy/files/html/31966D0005_DE.html | /home/edik/projects/eccjeu/data/raw/com_legacy/files/pdfs/31966D0005_DE.pdf | R9: /home/edik/projects/eccjeu/data/raw/com_legacy/files/html/31966D0005_DE.html | /home/edik/projects/eccjeu/data/raw/com_legacy/files/pdfs/31966D0005_DE.pdf | S9: /home/edik/projects/eccjeu/input/andrea_input.csv | /home/edik/projects/eccjeu/output/com_legacy/download_case_manifest.csv
A10: 24650 | B10: =YEAR(A10) -> 1967 | C10: 223 | D10: Exemption | Exemption Decision | E10: Transocean Marine Paint Association | F10: andrea | com_legacy | G10: 9 | com_legacy_1967_line_2 | H10: andrea:9 | com_legacy:com_legacy_1967_line_2 | I10: 223 | IV/223 | J10: 1967/06/27/223 | K10: 1967/06/27/223/andrea | 1967/06/27/223/com_legacy | L10: TRUE | M10: TRUE | N10: reference_only | already_downloaded | O10: http://ec.europa.eu/competition/antitrust/closed/en/1967.html | P10: https://eur-lex.europa.eu/legal-content/EN/TXT/HTML/?uri=CELEX:31967D0454 | https://eur-lex.europa.eu/legal-content/EN/TXT/PDF/?uri=CELEX:31967D0454 | https://eur-lex.europa.eu/legal-content/DE/TXT/HTML/?uri=CELEX:31967D0454 | https://eur-lex.europa.eu/legal-content/DE/TXT/PDF/?uri=CELEX:31967D0454 | http://ec.europa.eu/competition/search.html | http://ec.europa.eu/competition/antitrust/closed/en/1967.html#top | Q10: /home/edik/projects/eccjeu/data/raw/com_legacy/files/html/31967D0454_DE.html | /home/edik/projects/eccjeu/data/raw/com_legacy/files/pdfs/31967D0454_DE.pdf | /home/edik/projects/eccjeu/data/raw/com_legacy/files/html/search.html | /home/edik/projects/eccjeu/data/raw/com_legacy/files/html/1967.html | R10: /home/edik/projects/eccjeu/data/raw/com_legacy/files/html/31967D0454_DE.html | /home/edik/projects/eccjeu/data/raw/com_legacy/files/pdfs/31967D0454_DE.pdf | /home/edik/projects/eccjeu/data/raw/com_legacy/files/html/search.html | /home/edik/projects/eccjeu/data/raw/com_legacy/files/html/1967.html | S10: /home/edik/projects/eccjeu/input/andrea_input.csv | /home/edik/projects/eccjeu/output/com_legacy/download_case_manifest.csv
A11: 24894 | B11: =YEAR(A11) -> 1968 | C11: 26352 | D11: Negative Clearance | Negative Clearance Decision | E11: Eurogypsum | F11: andrea | com_legacy | G11: 10 | com_legacy_1968_line_23 | H11: andrea:10 | com_legacy:com_legacy_1968_line_23 | I11: 26352 | IV/26352 | J11: 1968/02/26/26352 | K11: 1968/02/26/26352/andrea | 1968/02/26/26352/com_legacy | L11: TRUE | M11: TRUE | N11: reference_only | already_downloaded | O11: http://ec.europa.eu/competition/antitrust/closed/en/1968.html | P11: https://eur-lex.europa.eu/legal-content/EN/TXT/HTML/?uri=CELEX:31968D0128 | https://eur-lex.europa.eu/legal-content/EN/TXT/PDF/?uri=CELEX:31968D0128 | https://eur-lex.europa.eu/legal-content/DE/TXT/HTML/?uri=CELEX:31968D0128 | https://eur-lex.europa.eu/legal-content/DE/TXT/PDF/?uri=CELEX:31968D0128 | http://ec.europa.eu/competition/search.html | http://ec.europa.eu/competition/antitrust/closed/en/1968.html#top | Q11: /home/edik/projects/eccjeu/data/raw/com_legacy/files/html/31968D0128_DE.html | /home/edik/projects/eccjeu/data/raw/com_legacy/files/pdfs/31968D0128_DE.pdf | /home/edik/projects/eccjeu/data/raw/com_legacy/files/html/search.html | /home/edik/projects/eccjeu/data/raw/com_legacy/files/html/1968.html | R11: /home/edik/projects/eccjeu/data/raw/com_legacy/files/html/31968D0128_DE.html | /home/edik/projects/eccjeu/data/raw/com_legacy/files/pdfs/31968D0128_DE.pdf | /home/edik/projects/eccjeu/data/raw/com_legacy/files/html/search.html | /home/edik/projects/eccjeu/data/raw/com_legacy/files/html/1968.html | S11: /home/edik/projects/eccjeu/input/andrea_input.csv | /home/edik/projects/eccjeu/output/com_legacy/download_case_manifest.csv
A12: 25036 | B12: =YEAR(A12) -> 1968 | C12: 129 | D12: Negative Clearance | Negative Clearance Decision | E12: Socemas | F12: andrea | com_legacy | G12: 12 | com_legacy_1968_line_20 | H12: andrea:12 | com_legacy:com_legacy_1968_line_20 | I12: 129 | IV/129 | J12: 1968/07/17/129 | K12: 1968/07/17/129/andrea | 1968/07/17/129/com_legacy | L12: TRUE | M12: TRUE | N12: reference_only | already_downloaded | O12: http://ec.europa.eu/competition/antitrust/closed/en/1968.html | P12: https://eur-lex.europa.eu/legal-content/EN/TXT/HTML/?uri=CELEX:31968D0318 | https://eur-lex.europa.eu/legal-content/EN/TXT/PDF/?uri=CELEX:31968D0318 | https://eur-lex.europa.eu/legal-content/DE/TXT/HTML/?uri=CELEX:31968D0318 | https://eur-lex.europa.eu/legal-content/DE/TXT/PDF/?uri=CELEX:31968D0318 | Q12: /home/edik/projects/eccjeu/data/raw/com_legacy/files/html/31968D0318_DE.html | /home/edik/projects/eccjeu/data/raw/com_legacy/files/pdfs/31968D0318_DE.pdf | R12: /home/edik/projects/eccjeu/data/raw/com_legacy/files/html/31968D0318_DE.html | /home/edik/projects/eccjeu/data/raw/com_legacy/files/pdfs/31968D0318_DE.pdf | S12: /home/edik/projects/eccjeu/input/andrea_input.csv | /home/edik/projects/eccjeu/output/com_legacy/download_case_manifest.csv
A13: 25036 | B13: =YEAR(A13) -> 1968 | C13: 25140 | D13: Negative Clearance | Negative Clearance Decision | E13: Alliance Constructeurs Francais de Machines-Outils | Constructeurs Français de Machines-Outils | F13: andrea | com_legacy | G13: 11 | com_legacy_1968_line_17 | H13: andrea:11 | com_legacy:com_legacy_1968_line_17 | I13: 25140 | IV/25140 | J13: 1968/07/17/25140 | K13: 1968/07/17/25140/andrea | 1968/07/17/25140/com_legacy | L13: TRUE | M13: TRUE | N13: reference_only | already_downloaded | O13: http://ec.europa.eu/competition/antitrust/closed/en/1968.html | P13: https://eur-lex.europa.eu/legal-content/EN/TXT/HTML/?uri=CELEX:31968D0317 | https://eur-lex.europa.eu/legal-content/EN/TXT/PDF/?uri=CELEX:31968D0317 | https://eur-lex.europa.eu/legal-content/DE/TXT/HTML/?uri=CELEX:31968D0317 | https://eur-lex.europa.eu/legal-content/DE/TXT/PDF/?uri=CELEX:31968D0317 | Q13: /home/edik/projects/eccjeu/data/raw/com_legacy/files/html/31968D0317_DE.html | /home/edik/projects/eccjeu/data/raw/com_legacy/files/pdfs/31968D0317_DE.pdf | R13: /home/edik/projects/eccjeu/data/raw/com_legacy/files/html/31968D0317_DE.html | /home/edik/projects/eccjeu/data/raw/com_legacy/files/pdfs/31968D0317_DE.pdf | S13: /home/edik/projects/eccjeu/input/andrea_input.csv | /home/edik/projects/eccjeu/output/com_legacy/download_case_manifest.csv
... A173: 29929 | B173: =YEAR(A173) -> 1981 | C173: 30307 | D173: Infringement | Procedural Decision | E173: FIRE INSURANCE (D) | F173: andrea | com_legacy | G173: 170 | com_legacy_1981_line_11 | H173: andrea:170 | com_legacy:com_legacy_1981_line_11 | I173: 30307 | IV/30307 | J173: 1981/09/12/30307 | K173: 1981/09/12/30307/andrea | 1981/09/12/30307/com_legacy | L173: TRUE | M173: TRUE | N173: reference_only | already_downloaded | O173: http://ec.europa.eu/competition/antitrust/closed/en/1981.html | P173: https://eur-lex.europa.eu/legal-content/EN/TXT/HTML/?uri=CELEX:31982D0174 | https://eur-lex.europa.eu/legal-content/EN/TXT/PDF/?uri=CELEX:31982D0174 | https://eur-lex.europa.eu/legal-content/DE/TXT/HTML/?uri=CELEX:31982D0174 | https://eur-lex.europa.eu/legal-content/DE/TXT/PDF/?uri=CELEX:31982D0174 | Q173: /home/edik/projects/eccjeu/data/raw/com_legacy/files/html/31982D0174_EN.html | /home/edik/projects/eccjeu/data/raw/com_legacy/files/pdfs/31982D0174_EN.pdf | /home/edik/projects/eccjeu/data/raw/com_legacy/files/html/31982D0174_DE.html | R173: /home/edik/projects/eccjeu/data/raw/com_legacy/files/html/31982D0174_EN.html | /home/edik/projects/eccjeu/data/raw/com_legacy/files/pdfs/31982D0174_EN.pdf | /home/edik/projects/eccjeu/data/raw/com_legacy/files/html/31982D0174_DE.html | S173: /home/edik/projects/eccjeu/input/andrea_input.csv | /home/edik/projects/eccjeu/output/com_legacy/download_case_manifest.csv
A174: 29931 | B174: =YEAR(A174) -> 1981 | C174: 511 | D174: Infringement | E174: National Panasonic France | F174: andrea | manual | G174: 172 | manual_000001 | H174: andrea:172 | manual:manual_000001 | I174: 511 | IV/511 | J174: 1981/11/12/511 | K174: 1981/11/12/511/andrea | 1981/11/12/511/manual | L174: TRUE | M174: FALSE | N174: reference_only | manual_injection | P174: https://eur-lex.europa.eu/legal-content/EN/TXT/HTML/?uri=CELEX:31982D0465&qid=1783330337429 | S174: /home/edik/projects/eccjeu/input/andrea_input.csv | /home/edik/projects/eccjeu/input/commission_manual_injection.csv
A175: 29931 | B175: =YEAR(A175) -> 1981 | C175: 512 | D175: Infringement | Decision imposing fines | E175: National Panasonic (Belgique) | Panasonic (France) | F175: andrea | com_legacy | G175: 171 | com_legacy_1981_line_5 | com_legacy_1981_line_8 | H175: andrea:171 | com_legacy:com_legacy_1981_line_5 | com_legacy:com_legacy_1981_line_8 | I175: 512 | IV/512 | J175: 1981/11/12/512 | K175: 1981/11/12/512/andrea | 1981/11/12/512/com_legacy | L175: TRUE | M175: TRUE | N175: reference_only | already_downloaded | O175: http://ec.europa.eu/competition/antitrust/closed/en/1981.html | P175: https://eur-lex.europa.eu/legal-content/EN/TXT/HTML/?uri=CELEX:31982D0260 | https://eur-lex.europa.eu/legal-content/EN/TXT/PDF/?uri=CELEX:31982D0260 | https://eur-lex.europa.eu/legal-content/DE/TXT/HTML/?uri=CELEX:31982D0260 | https://eur-lex.europa.eu/legal-content/DE/TXT/PDF/?uri=CELEX:31982D0260 | https://eur-lex.europa.eu/legal-content/EN/TXT/HTML/?uri=CELEX:31982D0465 | https://eur-lex.europa.eu/legal-content/EN/TXT/PDF/?uri=CELEX:31982D0465 | https://eur-lex.europa.eu/legal-content/DE/TXT/HTML/?uri=CELEX:31982D0465 | https://eur-lex.europa.eu/legal-content/DE/TXT/PDF/?uri=CELEX:31982D0465 | Q175: /home/edik/projects/eccjeu/data/raw/com_legacy/files/html/31982D0260_EN.html | /home/edik/projects/eccjeu/data/raw/com_legacy/files/pdfs/31982D0260_EN.pdf | /home/edik/projects/eccjeu/data/raw/com_legacy/files/html/31982D0260_DE.html | /home/edik/projects/eccjeu/data/raw/com_legacy/files/html/31982D0465_EN.html | /home/edik/projects/eccjeu/data/raw/com_legacy/files/pdfs/31982D0465_EN.pdf | /home/edik/projects/eccjeu/data/raw/com_legacy/files/html/31982D0465_DE.html | R175: /home/edik/projects/eccjeu/data/raw/com_legacy/files/html/31982D0260_EN.html | /home/edik/projects/eccjeu/data/raw/com_legacy/files/pdfs/31982D0260_EN.pdf | /home/edik/projects/eccjeu/data/raw/com_legacy/files/html/31982D0260_DE.html | /home/edik/projects/eccjeu/data/raw/com_legacy/files/html/31982D0465_EN.html | /home/edik/projects/eccjeu/data/raw/com_legacy/files/pdfs/31982D0465_EN.pdf | /home/edik/projects/eccjeu/data/raw/com_legacy/files/html/31982D0465_DE.html | S175: /home/edik/projects/eccjeu/input/andrea_input.csv | /home/edik/projects/eccjeu/output/com_legacy/download_case_manifest.csv
A176: 29937 | B176: =YEAR(A176) -> 1981 | C176: 29995 | D176: Infringement | not_exclusion_candidate | Prohibition Decision | E176: NAVEWA - ANSEAU | NA VEWA-ANSEAU | NAVEWA-ANSEAU | F176: andrea | com_db_comp | com_legacy | G176: 173 | 1622 | com_legacy_1981_line_2 | H176: andrea:173 | com_db_comp:1622 | com_legacy:com_legacy_1981_line_2 | I176: 29995 | IV/29995 | J176: 1981/12/17/29995 | K176: 1981/12/17/29995/andrea | 1981/12/17/29995/com_db_comp | 1981/12/17/29995/com_legacy | L176: TRUE | M176: TRUE | N176: reference_only | already_downloaded | O176: https://db-comp.eu/document_1622.download | http://ec.europa.eu/competition/antitrust/closed/en/1981.html | P176: https://db-comp.eu/document_1622.download | https://eur-lex.europa.eu/legal-content/EN/TXT/HTML/?uri=CELEX:31982D0371 | https://eur-lex.europa.eu/legal-content/EN/TXT/PDF/?uri=CELEX:31982D0371 | https://eur-lex.europa.eu/legal-content/DE/TXT/HTML/?uri=CELEX:31982D0371 | https://eur-lex.europa.eu/legal-content/DE/TXT/PDF/?uri=CELEX:31982D0371 | Q176: /home/edik/projects/eccjeu/data/raw/com_db_comp/files/29995-NAVEWA-ANSEAU-_Dec-1981_.pdf | /home/edik/projects/eccjeu/data/raw/com_legacy/files/html/31982D0371_EN.html | /home/edik/projects/eccjeu/data/raw/com_legacy/files/pdfs/31982D0371_EN.pdf | /home/edik/projects/eccjeu/data/raw/com_legacy/files/html/31982D0371_DE.html | R176: /home/edik/projects/eccjeu/data/raw/com_db_comp/files/29995-NAVEWA-ANSEAU-_Dec-1981_.pdf | /home/edik/projects/eccjeu/data/raw/com_legacy/files/html/31982D0371_EN.html | /home/edik/projects/eccjeu/data/raw/com_legacy/files/pdfs/31982D0371_EN.pdf | /home/edik/projects/eccjeu/data/raw/com_legacy/files/html/31982D0371_DE.html | S176: /home/edik/projects/eccjeu/input/andrea_input.csv | /home/edik/projects/eccjeu/output/com_db_comp/db_comp_metadata_manifest.csv | /home/edik/projects/eccjeu/output/com_legacy/download_case_manifest.csv
A177: 29957 | B177: =YEAR(A177) -> 1982 | C177: 28748 | D177: Infringement | not_exclusion_candidate | Prohibition Decision | E177: AEG-Telefunken | AEG - Telefunken | F177: andrea | com_db_comp | com_legacy | G177: 174 | 1677 | com_legacy_1982_line_38 | H177: andrea:174 | com_db_comp:1677 | com_legacy:com_legacy_1982_line_38 | I177: 28748 | IV/28748 | J177: 1982/06/01/28748 | K177: 1982/06/01/28748/andrea | 1982/06/01/28748/com_db_comp | 1982/06/01/28748/com_legacy | L177: TRUE | M177: TRUE | N177: reference_only | already_downloaded | O177: https://db-comp.eu/document_1677.download | http://ec.europa.eu/competition/antitrust/closed/en/1982.html | P177: https://db-comp.eu/document_1677.download | https://eur-lex.europa.eu/legal-content/EN/TXT/HTML/?uri=CELEX:31982D0267 | https://eur-lex.europa.eu/legal-content/EN/TXT/PDF/?uri=CELEX:31982D0267 | https://eur-lex.europa.eu/legal-content/DE/TXT/HTML/?uri=CELEX:31982D0267 | https://eur-lex.europa.eu/legal-content/DE/TXT/PDF/?uri=CELEX:31982D0267 | http://ec.europa.eu/competition/search.html | http://ec.europa.eu/competition/antitrust/closed/en/1982.html#top | Q177: /home/edik/projects/eccjeu/data/raw/com_db_comp/files/28748-AEG-Telefunken-_Jan-1982_.pdf | /home/edik/projects/eccjeu/data/raw/com_legacy/files/html/31982D0267_EN.html | /home/edik/projects/eccjeu/data/raw/com_legacy/files/pdfs/31982D0267_EN.pdf | /home/edik/projects/eccjeu/data/raw/com_legacy/files/html/31982D0267_DE.html | /home/edik/projects/eccjeu/data/raw/com_legacy/files/html/search.html | /home/edik/projects/eccjeu/data/raw/com_legacy/files/html/1982.html | R177: /home/edik/projects/eccjeu/data/raw/com_db_comp/files/28748-AEG-Telefunken-_Jan-1982_.pdf | /home/edik/projects/eccjeu/data/raw/com_legacy/files/html/31982D0267_EN.html | /home/edik/projects/eccjeu/data/raw/com_legacy/files/pdfs/31982D0267_EN.pdf | /home/edik/projects/eccjeu/data/raw/com_legacy/files/html/31982D0267_DE.html | /home/edik/projects/eccjeu/data/raw/com_legacy/files/html/search.html | /home/edik/projects/eccjeu/data/raw/com_legacy/files/html/1982.html | S177: /home/edik/projects/eccjeu/input/andrea_input.csv | /home/edik/projects/eccjeu/output/com_db_comp/db_comp_metadata_manifest.csv | /home/edik/projects/eccjeu/output/com_legacy/download_case_manifest.csv
A178: 30071 | B178: =YEAR(A178) -> 1982 | C178: 417 | D178: Exemption | Exemption Decision | E178: BPICA | F178: andrea | com_legacy | G178: 175 | com_legacy_1982_line_35 | H178: andrea:175 | com_legacy:com_legacy_1982_line_35 | I178: 417 | IV/417 | J178: 1982/04/30/417 | K178: 1982/04/30/417/andrea | 1982/04/30/417/com_legacy | L178: TRUE | M178: TRUE | N178: reference_only | already_downloaded | O178: http://ec.europa.eu/competition/antitrust/closed/en/1982.html | P178: https://eur-lex.europa.eu/legal-content/EN/TXT/HTML/?uri=CELEX:31982D0349 | https://eur-lex.europa.eu/legal-content/EN/TXT/PDF/?uri=CELEX:31982D0349 | https://eur-lex.europa.eu/legal-content/DE/TXT/HTML/?uri=CELEX:31982D0349 | https://eur-lex.europa.eu/legal-content/DE/TXT/PDF/?uri=CELEX:31982D0349 | Q178: /home/edik/projects/eccjeu/data/raw/com_legacy/files/html/31982D0349_EN.html | /home/edik/projects/eccjeu/data/raw/com_legacy/files/pdfs/31982D0349_EN.pdf | /home/edik/projects/eccjeu/data/raw/com_legacy/files/html/31982D0349_DE.html | R178: /home/edik/projects/eccjeu/data/raw/com_legacy/files/html/31982D0349_EN.html | /home/edik/projects/eccjeu/data/raw/com_legacy/files/pdfs/31982D0349_EN.pdf | /home/edik/projects/eccjeu/data/raw/com_legacy/files/html/31982D0349_DE.html | S178: /home/edik/projects/eccjeu/input/andrea_input.csv | /home/edik/projects/eccjeu/output/com_legacy/download_case_manifest.csv
A179: 30147 | B179: =YEAR(A179) -> 1982 | C179: 29525; 30000 | D179: Infringement | not_exclusion_candidate | Prohibition Decision | E179: SSI | F179: andrea | com_db_comp | com_legacy | G179: 176 | 1638 | com_legacy_1982_line_32 | H179: andrea:176 | com_db_comp:1638 | com_legacy:com_legacy_1982_line_32 | I179: 29525, 30000 | 29525 | 30000 | IV/29525 | IV/30000 | J179: 1982/07/15/29525/30000 | K179: 1982/07/15/29525/30000/andrea | 1982/07/15/29525/30000/com_db_comp | 1982/07/15/29525/30000/com_legacy | L179: TRUE | M179: TRUE | N179: reference_only | already_downloaded | O179: https://db-comp.eu/document_1638.download | http://ec.europa.eu/competition/antitrust/closed/en/1982.html | P179: https://db-comp.eu/document_1638.download | https://eur-lex.europa.eu/legal-content/EN/TXT/HTML/?uri=CELEX:31982D0506 | https://eur-lex.europa.eu/legal-content/EN/TXT/PDF/?uri=CELEX:31982D0506 | https://eur-lex.europa.eu/legal-content/DE/TXT/HTML/?uri=CELEX:31982D0506 | https://eur-lex.europa.eu/legal-content/DE/TXT/PDF/?uri=CELEX:31982D0506 | Q179: /home/edik/projects/eccjeu/data/raw/com_db_comp/files/29525-30000-SSI-_July-1982_.pdf | /home/edik/projects/eccjeu/data/raw/com_legacy/files/html/31982D0506_EN.html | /home/edik/projects/eccjeu/data/raw/com_legacy/files/pdfs/31982D0506_EN.pdf | /home/edik/projects/eccjeu/data/raw/com_legacy/files/html/31982D0506_DE.html | R179: /home/edik/projects/eccjeu/data/raw/com_db_comp/files/29525-30000-SSI-_July-1982_.pdf | /home/edik/projects/eccjeu/data/raw/com_legacy/files/html/31982D0506_EN.html | /home/edik/projects/eccjeu/data/raw/com_legacy/files/pdfs/31982D0506_EN.pdf | /home/edik/projects/eccjeu/data/raw/com_legacy/files/html/31982D0506_DE.html | S179: /home/edik/projects/eccjeu/input/andrea_input.csv | /home/edik/projects/eccjeu/output/com_db_comp/db_comp_metadata_manifest.csv | /home/edik/projects/eccjeu/output/com_legacy/download_case_manifest.csv
A180: 30181 | B180: =YEAR(A180) -> 1982 | C180: 30696 | D180: Interim Measures Decision | E180: FORD WERKE AG. | F180: com_legacy | G180: com_legacy_1982_line_29 | H180: com_legacy:com_legacy_1982_line_29 | I180: IV/30696 | J180: 1982/08/18/30696 | K180: 1982/08/18/30696/com_legacy | L180: TRUE | M180: TRUE | N180: already_downloaded | O180: http://ec.europa.eu/competition/antitrust/closed/en/1982.html | P180: https://eur-lex.europa.eu/legal-content/EN/TXT/HTML/?uri=CELEX:31982D0628 | https://eur-lex.europa.eu/legal-content/EN/TXT/PDF/?uri=CELEX:31982D0628 | https://eur-lex.europa.eu/legal-content/DE/TXT/HTML/?uri=CELEX:31982D0628 | https://eur-lex.europa.eu/legal-content/DE/TXT/PDF/?uri=CELEX:31982D0628 | Q180: /home/edik/projects/eccjeu/data/raw/com_legacy/files/html/31982D0628_EN.html | /home/edik/projects/eccjeu/data/raw/com_legacy/files/pdfs/31982D0628_EN.pdf | R180: /home/edik/projects/eccjeu/data/raw/com_legacy/files/html/31982D0628_EN.html | /home/edik/projects/eccjeu/data/raw/com_legacy/files/pdfs/31982D0628_EN.pdf | S180: /home/edik/projects/eccjeu/output/com_legacy/download_case_manifest.csv
A181: 30251 | B181: =YEAR(A181) -> 1982 | C181: 528 | D181: Infringement | Decision imposing fines | E181: Federation Nationale Chaussure de France | F181: andrea | com_legacy | G181: 177 | com_legacy_1982_line_26 | H181: andrea:177 | com_legacy:com_legacy_1982_line_26 | I181: 528 | IV/528 | J181: 1982/10/27/528 | K181: 1982/10/27/528/andrea | 1982/10/27/528/com_legacy | L181: TRUE | M181: TRUE | N181: reference_only | already_downloaded | O181: http://ec.europa.eu/competition/antitrust/closed/en/1982.html | P181: https://eur-lex.europa.eu/legal-content/EN/TXT/HTML/?uri=CELEX:31982D0756 | https://eur-lex.europa.eu/legal-content/EN/TXT/PDF/?uri=CELEX:31982D0756 | https://eur-lex.europa.eu/legal-content/DE/TXT/HTML/?uri=CELEX:31982D0756 | https://eur-lex.europa.eu/legal-content/DE/TXT/PDF/?uri=CELEX:31982D0756 | Q181: /home/edik/projects/eccjeu/data/raw/com_legacy/files/html/31982D0756_EN.html | /home/edik/projects/eccjeu/data/raw/com_legacy/files/pdfs/31982D0756_EN.pdf | /home/edik/projects/eccjeu/data/raw/com_legacy/files/html/31982D0756_DE.html | R181: /home/edik/projects/eccjeu/data/raw/com_legacy/files/html/31982D0756_EN.html | /home/edik/projects/eccjeu/data/raw/com_legacy/files/pdfs/31982D0756_EN.pdf | /home/edik/projects/eccjeu/data/raw/com_legacy/files/html/31982D0756_DE.html | S181: /home/edik/projects/eccjeu/input/andrea_input.csv | /home/edik/projects/eccjeu/output/com_legacy/download_case_manifest.csv
A182: 30253 | B182: =YEAR(A182) -> 1982 | C182: 30517 | D182: Exemption | not_exclusion_candidate | Exemption Decision | E182: AMERSHAM BUCHLER | Amersham Buchler | F182: andrea | com_db_comp | com_legacy | G182: 178 | 1599 | com_legacy_1982_line_23 | H182: andrea:178 | com_db_comp:1599 | com_legacy:com_legacy_1982_line_23 | I182: 30517 | IV/30517 | J182: 1982/10/29/30517 | K182: 1982/10/29/30517/andrea | 1982/10/29/30517/com_db_comp | 1982/10/29/30517/com_legacy | L182: TRUE | M182: TRUE | N182: reference_only | already_downloaded | O182: https://db-comp.eu/document_1599.download | http://ec.europa.eu/competition/antitrust/closed/en/1982.html | P182: https://db-comp.eu/document_1599.download | https://eur-lex.europa.eu/legal-content/EN/TXT/HTML/?uri=CELEX:31982D0742 | https://eur-lex.europa.eu/legal-content/EN/TXT/PDF/?uri=CELEX:31982D0742 | https://eur-lex.europa.eu/legal-content/DE/TXT/HTML/?uri=CELEX:31982D0742 | https://eur-lex.europa.eu/legal-content/DE/TXT/PDF/?uri=CELEX:31982D0742 | Q182: /home/edik/projects/eccjeu/data/raw/com_db_comp/files/30517-Amersham-Buchler-_Oct-1982_.pdf | /home/edik/projects/eccjeu/data/raw/com_legacy/files/html/31982D0742_EN.html | /home/edik/projects/eccjeu/data/raw/com_legacy/files/pdfs/31982D0742_EN.pdf | /home/edik/projects/eccjeu/data/raw/com_legacy/files/html/31982D0742_DE.html | R182: /home/edik/projects/eccjeu/data/raw/com_db_comp/files/30517-Amersham-Buchler-_Oct-1982_.pdf | /home/edik/projects/eccjeu/data/raw/com_legacy/files/html/31982D0742_EN.html | /home/edik/projects/eccjeu/data/raw/com_legacy/files/pdfs/31982D0742_EN.pdf | /home/edik/projects/eccjeu/data/raw/com_legacy/files/html/31982D0742_DE.html | S182: /home/edik/projects/eccjeu/input/andrea_input.csv | /home/edik/projects/eccjeu/output/com_db_comp/db_comp_metadata_manifest.csv | /home/edik/projects/eccjeu/output/com_legacy/download_case_manifest.csv
A183: 30259 | B183: =YEAR(A183) -> 1982 | C183: 29995 | D183: Amending Decision | E183: NAVEWA-ANSEAU (BOSCH) | F183: com_legacy | G183: com_legacy_1982_line_20 | H183: com_legacy:com_legacy_1982_line_20 | I183: IV/29995 | J183: 1982/04/11/29995 | K183: 1982/04/11/29995/com_legacy | L183: TRUE | M183: TRUE | N183: already_downloaded | O183: http://ec.europa.eu/competition/antitrust/closed/en/1982.html | P183: https://eur-lex.europa.eu/legal-content/EN/TXT/HTML/?uri=CELEX:31982D0777 | https://eur-lex.europa.eu/legal-content/EN/TXT/PDF/?uri=CELEX:31982D0777 | https://eur-lex.europa.eu/legal-content/DE/TXT/HTML/?uri=CELEX:31982D0777 | https://eur-lex.europa.eu/legal-content/DE/TXT/PDF/?uri=CELEX:31982D0777 | Q183: /home/edik/projects/eccjeu/data/raw/com_legacy/files/html/31982D0777_EN.html | /home/edik/projects/eccjeu/data/raw/com_legacy/files/pdfs/31982D0777_EN.pdf | /home/edik/projects/eccjeu/data/raw/com_legacy/files/html/31982D0777_DE.html | R183: /home/edik/projects/eccjeu/data/raw/com_legacy/files/html/31982D0777_EN.html | /home/edik/projects/eccjeu/data/raw/com_legacy/files/pdfs/31982D0777_EN.pdf | /home/edik/projects/eccjeu/data/raw/com_legacy/files/html/31982D0777_DE.html | S183: /home/edik/projects/eccjeu/output/com_legacy/download_case_manifest.csv
A184: 30292 | B184: =YEAR(A184) -> 1982 | C184: 30070 | D184: Infringement | not_exclusion_candidate | Prohibition Decision | E184: National Panasonic | F184: andrea | com_db_comp | com_legacy | G184: 179 | 1618 | com_legacy_1982_line_17 | H184: andrea:179 | com_db_comp:1618 | com_legacy:com_legacy_1982_line_17 | I184: 30070 | IV/30070 | J184: 1982/07/12/30070 | K184: 1982/07/12/30070/andrea | 1982/07/12/30070/com_db_comp | 1982/07/12/30070/com_legacy | L184: TRUE | M184: TRUE | N184: reference_only | already_downloaded | O184: https://db-comp.eu/document_1618.download | http://ec.europa.eu/competition/antitrust/closed/en/1982.html | P184: https://db-comp.eu/document_1618.download | https://eur-lex.europa.eu/legal-content/EN/TXT/HTML/?uri=CELEX:31982D0853 | https://eur-lex.europa.eu/legal-content/EN/TXT/PDF/?uri=CELEX:31982D0853 | https://eur-lex.europa.eu/legal-content/DE/TXT/HTML/?uri=CELEX:31982D0853 | https://eur-lex.europa.eu/legal-content/DE/TXT/PDF/?uri=CELEX:31982D0853 | Q184: /home/edik/projects/eccjeu/data/raw/com_db_comp/files/30070-National-Panasonic-_Dec-1982_.pdf | /home/edik/projects/eccjeu/data/raw/com_legacy/files/html/31982D0853_EN.html | /home/edik/projects/eccjeu/data/raw/com_legacy/files/pdfs/31982D0853_EN.pdf | /home/edik/projects/eccjeu/data/raw/com_legacy/files/html/31982D0853_DE.html | R184: /home/edik/projects/eccjeu/data/raw/com_db_comp/files/30070-National-Panasonic-_Dec-1982_.pdf | /home/edik/projects/eccjeu/data/raw/com_legacy/files/html/31982D0853_EN.html | /home/edik/projects/eccjeu/data/raw/com_legacy/files/pdfs/31982D0853_EN.pdf | /home/edik/projects/eccjeu/data/raw/com_legacy/files/html/31982D0853_DE.html | S184: /home/edik/projects/eccjeu/input/andrea_input.csv | /home/edik/projects/eccjeu/output/com_db_comp/db_comp_metadata_manifest.csv | /home/edik/projects/eccjeu/output/com_legacy/download_case_manifest.csv
A185: 30295 | B185: =YEAR(A185) -> 1982 | C185: 29877 | D185: Infringement | not_exclusion_candidate | Prohibition Decision | E185: British Telecommunications | F185: andrea | com_db_comp | com_legacy | G185: 181 | 1817 | com_legacy_1982_line_11 | H185: andrea:181 | com_db_comp:1817 | com_legacy:com_legacy_1982_line_11 | I185: 29877 | IV/29877 | J185: 1982/10/12/29877 | K185: 1982/10/12/29877/andrea | 1982/10/12/29877/com_db_comp | 1982/10/12/29877/com_legacy | L185: TRUE | M185: TRUE | N185: reference_only | already_downloaded | O185: https://db-comp.eu/document_1817.download | http://ec.europa.eu/competition/antitrust/closed/en/1982.html | P185: https://db-comp.eu/document_1817.download | https://eur-lex.europa.eu/legal-content/EN/TXT/HTML/?uri=CELEX:31982D0861 | https://eur-lex.europa.eu/legal-content/EN/TXT/PDF/?uri=CELEX:31982D0861 | https://eur-lex.europa.eu/legal-content/DE/TXT/HTML/?uri=CELEX:31982D0861 | https://eur-lex.europa.eu/legal-content/DE/TXT/PDF/?uri=CELEX:31982D0861 | Q185: /home/edik/projects/eccjeu/data/raw/com_db_comp/files/29877-British-Telecommunications.pdf | /home/edik/projects/eccjeu/data/raw/com_legacy/files/html/31982D0861_EN.html | /home/edik/projects/eccjeu/data/raw/com_legacy/files/pdfs/31982D0861_EN.pdf | /home/edik/projects/eccjeu/data/raw/com_legacy/files/html/31982D0861_DE.html | R185: /home/edik/projects/eccjeu/data/raw/com_db_comp/files/29877-British-Telecommunications.pdf | /home/edik/projects/eccjeu/data/raw/com_legacy/files/html/31982D0861_EN.html | /home/edik/projects/eccjeu/data/raw/com_legacy/files/pdfs/31982D0861_EN.pdf | /home/edik/projects/eccjeu/data/raw/com_legacy/files/html/31982D0861_DE.html | S185: /home/edik/projects/eccjeu/input/andrea_input.csv | /home/edik/projects/eccjeu/output/com_db_comp/db_comp_metadata_manifest.csv | /home/edik/projects/eccjeu/output/com_legacy/download_case_manifest.csv
A186: 30295 | B186: =YEAR(A186) -> 1982 | C186: 30077 | D186: Infringement | not_exclusion_candidate | Prohibition Decision | E186: Cafeteros de Colombia (FNC) | Cafeteros de Colombia | Cafeteros de Colomba | F186: andrea | com_db_comp | com_legacy | G186: 180 | 1617 | com_legacy_1982_line_14 | H186: andrea:180 | com_db_comp:1617 | com_legacy:com_legacy_1982_line_14 | I186: 30077 | IV/30077 | J186: 1982/10/12/30077 | K186: 1982/10/12/30077/andrea | 1982/10/12/30077/com_db_comp | 1982/10/12/30077/com_legacy | L186: TRUE | M186: TRUE | N186: reference_only | already_downloaded | O186: https://db-comp.eu/document_1617.download | http://ec.europa.eu/competition/antitrust/closed/en/1982.html | P186: https://db-comp.eu/document_1617.download | https://eur-lex.europa.eu/legal-content/EN/TXT/HTML/?uri=CELEX:31982D0860 | https://eur-lex.europa.eu/legal-content/EN/TXT/PDF/?uri=CELEX:31982D0860 | https://eur-lex.europa.eu/legal-content/DE/TXT/HTML/?uri=CELEX:31982D0860 | https://eur-lex.europa.eu/legal-content/DE/TXT/PDF/?uri=CELEX:31982D0860 | Q186: /home/edik/projects/eccjeu/data/raw/com_db_comp/files/30077-Cafeteros-de-Colombia-_Dec-1982_.pdf | /home/edik/projects/eccjeu/data/raw/com_legacy/files/html/31982D0860_EN.html | /home/edik/projects/eccjeu/data/raw/com_legacy/files/pdfs/31982D0860_EN.pdf | /home/edik/projects/eccjeu/data/raw/com_legacy/files/html/31982D0860_DE.html | R186: /home/edik/projects/eccjeu/data/raw/com_db_comp/files/30077-Cafeteros-de-Colombia-_Dec-1982_.pdf | /home/edik/projects/eccjeu/data/raw/com_legacy/files/html/31982D0860_EN.html | /home/edik/projects/eccjeu/data/raw/com_legacy/files/pdfs/31982D0860_EN.pdf | /home/edik/projects/eccjeu/data/raw/com_legacy/files/html/31982D0860_DE.html | S186: /home/edik/projects/eccjeu/input/andrea_input.csv | /home/edik/projects/eccjeu/output/com_db_comp/db_comp_metadata_manifest.csv | /home/edik/projects/eccjeu/output/com_legacy/download_case_manifest.csv
... A227: 31070 | B227: =YEAR(A227) -> 1985 | C227: 31163 | D227: Infringement | Procedural Decision | E227: OLYMPIC AIRWAYS | F227: andrea | com_legacy | G227: 221 | com_legacy_1985_line_50 | H227: andrea:221 | com_legacy:com_legacy_1985_line_50 | I227: 31163 | IV/31163 | J227: 1985/01/23/31163 | K227: 1985/01/23/31163/andrea | 1985/01/23/31163/com_legacy | L227: TRUE | M227: TRUE | N227: reference_only | already_downloaded | O227: http://ec.europa.eu/competition/antitrust/closed/en/1985.html | P227: https://eur-lex.europa.eu/legal-content/EN/TXT/HTML/?uri=CELEX:31985D0121 | https://eur-lex.europa.eu/legal-content/EN/TXT/PDF/?uri=CELEX:31985D0121 | https://eur-lex.europa.eu/legal-content/DE/TXT/HTML/?uri=CELEX:31985D0121 | https://eur-lex.europa.eu/legal-content/DE/TXT/PDF/?uri=CELEX:31985D0121 | http://ec.europa.eu/competition/search.html | http://ec.europa.eu/competition/antitrust/closed/en/1985.html#top | Q227: /home/edik/projects/eccjeu/data/raw/com_legacy/files/html/31985D0121_EN.html | /home/edik/projects/eccjeu/data/raw/com_legacy/files/pdfs/31985D0121_EN.pdf | /home/edik/projects/eccjeu/data/raw/com_legacy/files/html/31985D0121_DE.html | /home/edik/projects/eccjeu/data/raw/com_legacy/files/html/search.html | /home/edik/projects/eccjeu/data/raw/com_legacy/files/html/1985.html | R227: /home/edik/projects/eccjeu/data/raw/com_legacy/files/html/31985D0121_EN.html | /home/edik/projects/eccjeu/data/raw/com_legacy/files/pdfs/31985D0121_EN.pdf | /home/edik/projects/eccjeu/data/raw/com_legacy/files/html/31985D0121_DE.html | /home/edik/projects/eccjeu/data/raw/com_legacy/files/html/search.html | /home/edik/projects/eccjeu/data/raw/com_legacy/files/html/1985.html | S227: /home/edik/projects/eccjeu/input/andrea_input.csv | /home/edik/projects/eccjeu/output/com_legacy/download_case_manifest.csv
A228: 31161 | B228: =YEAR(A228) -> 1985 | D228: Infringement | E228: Greek Insurance | F228: andrea | manual | G228: 222 | manual_000004 | H228: andrea:222 | manual:manual_000004 | J228: 1985/04/24/missing_case | K228: 1985/04/24/missing_case/andrea | 1985/04/24/missing_case/manual | L228: TRUE | M228: FALSE | N228: reference_only | manual_injection | P228: https://eur-lex.europa.eu/legal-content/EN/TXT/HTML/?uri=CELEX%3A31985D0276 | S228: /home/edik/projects/eccjeu/input/andrea_input.csv | /home/edik/projects/eccjeu/input/commission_manual_injection.csv
A229: 31238 | B229: =YEAR(A229) -> 1985 | C229: 29420 | D229: Exemption | not_exclusion_candidate | Exemption Decision | E229: GRUNDIG | Grundig's EEC distribution system | F229: andrea | com_db_comp | com_legacy | G229: 224 | 1644 | com_legacy_1985_line_47 | H229: andrea:224 | com_db_comp:1644 | com_legacy:com_legacy_1985_line_47 | I229: 29420 | J229: 1985/10/07/29420 | 1985/10/07/4 | K229: 1985/10/07/29420/andrea | 1985/10/07/29420/com_db_comp | 1985/10/07/4/com_legacy | L229: TRUE | M229: TRUE | N229: reference_only | already_downloaded | O229: https://db-comp.eu/document_1644.download | http://ec.europa.eu/competition/antitrust/closed/en/1985.html | P229: https://db-comp.eu/document_1644.download | https://eur-lex.europa.eu/legal-content/EN/TXT/HTML/?uri=CELEX:31985D0404 | https://eur-lex.europa.eu/legal-content/EN/TXT/PDF/?uri=CELEX:31985D0404 | https://eur-lex.europa.eu/legal-content/DE/TXT/HTML/?uri=CELEX:31985D0404 | https://eur-lex.europa.eu/legal-content/DE/TXT/PDF/?uri=CELEX:31985D0404 | Q229: /home/edik/projects/eccjeu/data/raw/com_db_comp/files/29420-Grundig-s-EEC-distribution-system-_July-1985_.pdf | /home/edik/projects/eccjeu/data/raw/com_legacy/files/html/31985D0404_EN.html | /home/edik/projects/eccjeu/data/raw/com_legacy/files/pdfs/31985D0404_EN.pdf | /home/edik/projects/eccjeu/data/raw/com_legacy/files/html/31985D0404_DE.html | R229: /home/edik/projects/eccjeu/data/raw/com_db_comp/files/29420-Grundig-s-EEC-distribution-system-_July-1985_.pdf | /home/edik/projects/eccjeu/data/raw/com_legacy/files/html/31985D0404_EN.html | /home/edik/projects/eccjeu/data/raw/com_legacy/files/pdfs/31985D0404_EN.pdf | /home/edik/projects/eccjeu/data/raw/com_legacy/files/html/31985D0404_DE.html | S229: /home/edik/projects/eccjeu/input/andrea_input.csv | /home/edik/projects/eccjeu/output/com_db_comp/db_comp_metadata_manifest.csv | /home/edik/projects/eccjeu/output/com_legacy/download_case_manifest.csv
A230: 31238 | B230: =YEAR(A230) -> 1985 | C230: 31029 | D230: Infringement | not_exclusion_candidate | Prohibition Decision | E230: EATE LEVY | French inland waterway charter traffic: EATE levy | F230: andrea | com_db_comp | com_legacy | G230: 223 | 1570 | com_legacy_1985_line_44 | H230: andrea:223 | com_db_comp:1570 | com_legacy:com_legacy_1985_line_44 | I230: 31029 | IV/31029 | J230: 1985/10/07/31029 | K230: 1985/10/07/31029/andrea | 1985/10/07/31029/com_db_comp | 1985/10/07/31029/com_legacy | L230: TRUE | M230: TRUE | N230: reference_only | already_downloaded | O230: https://db-comp.eu/document_1570.download | http://ec.europa.eu/competition/antitrust/closed/en/1985.html | P230: https://db-comp.eu/document_1570.download | https://eur-lex.europa.eu/legal-content/EN/TXT/HTML/?uri=CELEX:31985D0383 | https://eur-lex.europa.eu/legal-content/EN/TXT/PDF/?uri=CELEX:31985D0383 | https://eur-lex.europa.eu/legal-content/DE/TXT/HTML/?uri=CELEX:31985D0383 | https://eur-lex.europa.eu/legal-content/DE/TXT/PDF/?uri=CELEX:31985D0383 | Q230: /home/edik/projects/eccjeu/data/raw/com_db_comp/files/31029-French-inland-waterway-charter-traffic-EATE-levy-_July-1985_.pdf | /home/edik/projects/eccjeu/data/raw/com_legacy/files/html/31985D0383_EN.html | /home/edik/projects/eccjeu/data/raw/com_legacy/files/pdfs/31985D0383_EN.pdf | /home/edik/projects/eccjeu/data/raw/com_legacy/files/html/31985D0383_DE.html | R230: /home/edik/projects/eccjeu/data/raw/com_db_comp/files/31029-French-inland-waterway-charter-traffic-EATE-levy-_July-1985_.pdf | /home/edik/projects/eccjeu/data/raw/com_legacy/files/html/31985D0383_EN.html | /home/edik/projects/eccjeu/data/raw/com_legacy/files/pdfs/31985D0383_EN.pdf | /home/edik/projects/eccjeu/data/raw/com_legacy/files/html/31985D0383_DE.html | S230: /home/edik/projects/eccjeu/input/andrea_input.csv | /home/edik/projects/eccjeu/output/com_db_comp/db_comp_metadata_manifest.csv | /home/edik/projects/eccjeu/output/com_legacy/download_case_manifest.csv
A231: 31240 | B231: =YEAR(A231) -> 1985 | C231: 4204 | D231: Infringement | not_exclusion_candidate | Prohibition Decision | E231: VELCRO-APLIX | Velcro/Aplix | F231: andrea | com_db_comp | com_legacy | G231: 225 | 1753 | com_legacy_1985_line_41 | H231: andrea:225 | com_db_comp:1753 | com_legacy:com_legacy_1985_line_41 | I231: 4204 | IV/4204 | J231: 1985/12/07/4204 | K231: 1985/12/07/4204/andrea | 1985/12/07/4204/com_db_comp | 1985/12/07/4204/com_legacy | L231: TRUE | M231: TRUE | N231: reference_only | already_downloaded | O231: https://db-comp.eu/document_1753.download | http://ec.europa.eu/competition/antitrust/closed/en/1985.html | P231: https://db-comp.eu/document_1753.download | https://eur-lex.europa.eu/legal-content/EN/TXT/HTML/?uri=CELEX:31985D0410 | https://eur-lex.europa.eu/legal-content/EN/TXT/PDF/?uri=CELEX:31985D0410 | https://eur-lex.europa.eu/legal-content/DE/TXT/HTML/?uri=CELEX:31985D0410 | https://eur-lex.europa.eu/legal-content/DE/TXT/PDF/?uri=CELEX:31985D0410 | Q231: /home/edik/projects/eccjeu/data/raw/com_db_comp/files/4204-Velcro-Aplix-_July-1985_.pdf | /home/edik/projects/eccjeu/data/raw/com_legacy/files/html/31985D0410_EN.html | /home/edik/projects/eccjeu/data/raw/com_legacy/files/pdfs/31985D0410_EN.pdf | /home/edik/projects/eccjeu/data/raw/com_legacy/files/html/31985D0410_DE.html | R231: /home/edik/projects/eccjeu/data/raw/com_db_comp/files/4204-Velcro-Aplix-_July-1985_.pdf | /home/edik/projects/eccjeu/data/raw/com_legacy/files/html/31985D0410_EN.html | /home/edik/projects/eccjeu/data/raw/com_legacy/files/pdfs/31985D0410_EN.pdf | /home/edik/projects/eccjeu/data/raw/com_legacy/files/html/31985D0410_DE.html | S231: /home/edik/projects/eccjeu/input/andrea_input.csv | /home/edik/projects/eccjeu/output/com_db_comp/db_comp_metadata_manifest.csv | /home/edik/projects/eccjeu/output/com_legacy/download_case_manifest.csv
A232: 31378 | B232: =YEAR(A232) -> 1985 | C232: 30846 | D232: Exemption | not_exclusion_candidate | Exemption Decision | E232: IVOCLAR | lvoclar | F232: andrea | com_db_comp | com_legacy | G232: 226 | 1579 | com_legacy_1985_line_38 | H232: andrea:226 | com_db_comp:1579 | com_legacy:com_legacy_1985_line_38 | I232: 30846 | IV/30846 | J232: 1985/11/27/30846 | K232: 1985/11/27/30846/andrea | 1985/11/27/30846/com_db_comp | 1985/11/27/30846/com_legacy | L232: TRUE | M232: TRUE | N232: reference_only | already_downloaded | O232: https://db-comp.eu/document_1579.download | http://ec.europa.eu/competition/antitrust/closed/en/1985.html | P232: https://db-comp.eu/document_1579.download | https://eur-lex.europa.eu/legal-content/EN/TXT/HTML/?uri=CELEX:31985D0559 | https://eur-lex.europa.eu/legal-content/EN/TXT/PDF/?uri=CELEX:31985D0559 | https://eur-lex.europa.eu/legal-content/DE/TXT/HTML/?uri=CELEX:31985D0559 | https://eur-lex.europa.eu/legal-content/DE/TXT/PDF/?uri=CELEX:31985D0559 | Q232: /home/edik/projects/eccjeu/data/raw/com_db_comp/files/30846-Ivoclar-_Nov-1985_.pdf | /home/edik/projects/eccjeu/data/raw/com_legacy/files/html/31985D0559_EN.html | /home/edik/projects/eccjeu/data/raw/com_legacy/files/pdfs/31985D0559_EN.pdf | /home/edik/projects/eccjeu/data/raw/com_legacy/files/html/31985D0559_DE.html | R232: /home/edik/projects/eccjeu/data/raw/com_db_comp/files/30846-Ivoclar-_Nov-1985_.pdf | /home/edik/projects/eccjeu/data/raw/com_legacy/files/html/31985D0559_EN.html | /home/edik/projects/eccjeu/data/raw/com_legacy/files/pdfs/31985D0559_EN.pdf | /home/edik/projects/eccjeu/data/raw/com_legacy/files/html/31985D0559_DE.html | S232: /home/edik/projects/eccjeu/input/andrea_input.csv | /home/edik/projects/eccjeu/output/com_db_comp/db_comp_metadata_manifest.csv | /home/edik/projects/eccjeu/output/com_legacy/download_case_manifest.csv
A233: 31383 | B233: =YEAR(A233) -> 1985 | C233: 30971 | D233: Exemption | not_exclusion_candidate | Exemption Decision | E233: BP/KELLOGG | BP/Kellogg | F233: andrea | com_db_comp | com_legacy | G233: 227 | 1574 | com_legacy_1985_line_35 | H233: andrea:227 | com_db_comp:1574 | com_legacy:com_legacy_1985_line_35 | I233: 30971 | IV/30971 | J233: 1985/02/12/30971 | K233: 1985/02/12/30971/andrea | 1985/02/12/30971/com_db_comp | 1985/02/12/30971/com_legacy | L233: TRUE | M233: TRUE | N233: reference_only | already_downloaded | O233: https://db-comp.eu/document_1574.download | http://ec.europa.eu/competition/antitrust/closed/en/1985.html | P233: https://db-comp.eu/document_1574.download | https://eur-lex.europa.eu/legal-content/EN/TXT/HTML/?uri=CELEX:31985D0560 | https://eur-lex.europa.eu/legal-content/EN/TXT/PDF/?uri=CELEX:31985D0560 | https://eur-lex.europa.eu/legal-content/DE/TXT/HTML/?uri=CELEX:31985D0560 | https://eur-lex.europa.eu/legal-content/DE/TXT/PDF/?uri=CELEX:31985D0560 | Q233: /home/edik/projects/eccjeu/data/raw/com_db_comp/files/30971-BP-Kellogg-_Dec-1985_.pdf | /home/edik/projects/eccjeu/data/raw/com_legacy/files/html/31985D0560_EN.html | /home/edik/projects/eccjeu/data/raw/com_legacy/files/pdfs/31985D0560_EN.pdf | /home/edik/projects/eccjeu/data/raw/com_legacy/files/html/31985D0560_DE.html | R233: /home/edik/projects/eccjeu/data/raw/com_db_comp/files/30971-BP-Kellogg-_Dec-1985_.pdf | /home/edik/projects/eccjeu/data/raw/com_legacy/files/html/31985D0560_EN.html | /home/edik/projects/eccjeu/data/raw/com_legacy/files/pdfs/31985D0560_EN.pdf | /home/edik/projects/eccjeu/data/raw/com_legacy/files/html/31985D0560_DE.html | S233: /home/edik/projects/eccjeu/input/andrea_input.csv | /home/edik/projects/eccjeu/output/com_db_comp/db_comp_metadata_manifest.csv | /home/edik/projects/eccjeu/output/com_legacy/download_case_manifest.csv
A234: 31394 | B234: =YEAR(A234) -> 1985 | C234: 27590 | D234: Negative Clearance | not_exclusion_candidate | Negative Clearance Decision | E234: London Sugar Futures Market Ltd | London Sugar Futures Market Limited | F234: andrea | com_db_comp | com_legacy | G234: 230 | 1687 | com_legacy_1985_line_29 | H234: andrea:230 | com_db_comp:1687 | com_legacy:com_legacy_1985_line_29 | I234: 27590 | IV/27590 | J234: 1985/12/13/27590 | K234: 1985/12/13/27590/andrea | 1985/12/13/27590/com_db_comp | 1985/12/13/27590/com_legacy | L234: TRUE | M234: TRUE | N234: reference_only | already_downloaded | O234: https://db-comp.eu/document_1687.download | http://ec.europa.eu/competition/antitrust/closed/en/1985.html | P234: https://db-comp.eu/document_1687.download | https://eur-lex.europa.eu/legal-content/EN/TXT/HTML/?uri=CELEX:31985D0563 | https://eur-lex.europa.eu/legal-content/EN/TXT/PDF/?uri=CELEX:31985D0563 | https://eur-lex.europa.eu/legal-content/DE/TXT/HTML/?uri=CELEX:31985D0563 | https://eur-lex.europa.eu/legal-content/DE/TXT/PDF/?uri=CELEX:31985D0563 | Q234: /home/edik/projects/eccjeu/data/raw/com_db_comp/files/27590-London-Sugar-Futures-Market-Limited-_Dec-1985_.pdf | /home/edik/projects/eccjeu/data/raw/com_legacy/files/html/31985D0563_EN.html | /home/edik/projects/eccjeu/data/raw/com_legacy/files/pdfs/31985D0563_EN.pdf | /home/edik/projects/eccjeu/data/raw/com_legacy/files/html/31985D0563_DE.html | R234: /home/edik/projects/eccjeu/data/raw/com_db_comp/files/27590-London-Sugar-Futures-Market-Limited-_Dec-1985_.pdf | /home/edik/projects/eccjeu/data/raw/com_legacy/files/html/31985D0563_EN.html | /home/edik/projects/eccjeu/data/raw/com_legacy/files/pdfs/31985D0563_EN.pdf | /home/edik/projects/eccjeu/data/raw/com_legacy/files/html/31985D0563_DE.html | S234: /home/edik/projects/eccjeu/input/andrea_input.csv | /home/edik/projects/eccjeu/output/com_db_comp/db_comp_metadata_manifest.csv | /home/edik/projects/eccjeu/output/com_legacy/download_case_manifest.csv
A235: 31394 | B235: =YEAR(A235) -> 1985 | C235: 27591 | D235: Negative Clearance | not_exclusion_candidate | Negative Clearance Decision | E235: London Cocoa Terminal Market Association Ltd | London Cocoa Terminal Market Association Limited | F235: andrea | com_db_comp | com_legacy | G235: 231 | 1686 | com_legacy_1985_line_23 | H235: andrea:231 | com_db_comp:1686 | com_legacy:com_legacy_1985_line_23 | I235: 27591 | IV/27591 | J235: 1985/12/13/27591 | K235: 1985/12/13/27591/andrea | 1985/12/13/27591/com_db_comp | 1985/12/13/27591/com_legacy | L235: TRUE | M235: TRUE | N235: reference_only | already_downloaded | O235: https://db-comp.eu/document_1686.download | http://ec.europa.eu/competition/antitrust/closed/en/1985.html | P235: https://db-comp.eu/document_1686.download | https://eur-lex.europa.eu/legal-content/EN/TXT/HTML/?uri=CELEX:31985D0564 | https://eur-lex.europa.eu/legal-content/EN/TXT/PDF/?uri=CELEX:31985D0564 | https://eur-lex.europa.eu/legal-content/DE/TXT/HTML/?uri=CELEX:31985D0564 | https://eur-lex.europa.eu/legal-content/DE/TXT/PDF/?uri=CELEX:31985D0564 | Q235: /home/edik/projects/eccjeu/data/raw/com_db_comp/files/27591-London-Cocoa-Terminal-Market-Association-Limited-_Dec-1985_.pdf | /home/edik/projects/eccjeu/data/raw/com_legacy/files/html/31985D0564_EN.html | /home/edik/projects/eccjeu/data/raw/com_legacy/files/pdfs/31985D0564_EN.pdf | /home/edik/projects/eccjeu/data/raw/com_legacy/files/html/31985D0564_DE.html | R235: /home/edik/projects/eccjeu/data/raw/com_db_comp/files/27591-London-Cocoa-Terminal-Market-Association-Limited-_Dec-1985_.pdf | /home/edik/projects/eccjeu/data/raw/com_legacy/files/html/31985D0564_EN.html | /home/edik/projects/eccjeu/data/raw/com_legacy/files/pdfs/31985D0564_EN.pdf | /home/edik/projects/eccjeu/data/raw/com_legacy/files/html/31985D0564_DE.html | S235: /home/edik/projects/eccjeu/input/andrea_input.csv | /home/edik/projects/eccjeu/output/com_db_comp/db_comp_metadata_manifest.csv | /home/edik/projects/eccjeu/output/com_legacy/download_case_manifest.csv
A236: 31394 | B236: =YEAR(A236) -> 1985 | C236: 27592 | D236: Negative Clearance | not_exclusion_candidate | Negative Clearance Decision | E236: Coffee Terminal Market Association Ltd | London Rubber Terminal Market Association Limited | Coffee Terminal Market Association of London Ltd | F236: andrea | com_db_comp | com_legacy | G236: 232 | 1685 | com_legacy_1985_line_20 | H236: andrea:232 | com_db_comp:1685 | com_legacy:com_legacy_1985_line_20 | I236: 27592 | IV/27592 | J236: 1985/12/13/27592 | K236: 1985/12/13/27592/andrea | 1985/12/13/27592/com_db_comp | 1985/12/13/27592/com_legacy | L236: TRUE | M236: TRUE | N236: reference_only | already_downloaded | O236: https://db-comp.eu/document_1685.download | http://ec.europa.eu/competition/antitrust/closed/en/1985.html | P236: https://db-comp.eu/document_1685.download | https://eur-lex.europa.eu/legal-content/EN/TXT/HTML/?uri=CELEX:31985D0565 | https://eur-lex.europa.eu/legal-content/EN/TXT/PDF/?uri=CELEX:31985D0565 | https://eur-lex.europa.eu/legal-content/DE/TXT/HTML/?uri=CELEX:31985D0565 | https://eur-lex.europa.eu/legal-content/DE/TXT/PDF/?uri=CELEX:31985D0565 | Q236: /home/edik/projects/eccjeu/data/raw/com_db_comp/files/27592-Coffee-Terminal-Market-Association-of-London-Limited-_Dec-1985_.pdf | /home/edik/projects/eccjeu/data/raw/com_legacy/files/html/31985D0565_EN.html | /home/edik/projects/eccjeu/data/raw/com_legacy/files/pdfs/31985D0565_EN.pdf | /home/edik/projects/eccjeu/data/raw/com_legacy/files/html/31985D0565_DE.html | R236: /home/edik/projects/eccjeu/data/raw/com_db_comp/files/27592-Coffee-Terminal-Market-Association-of-London-Limited-_Dec-1985_.pdf | /home/edik/projects/eccjeu/data/raw/com_legacy/files/html/31985D0565_EN.html | /home/edik/projects/eccjeu/data/raw/com_legacy/files/pdfs/31985D0565_EN.pdf | /home/edik/projects/eccjeu/data/raw/com_legacy/files/html/31985D0565_DE.html | S236: /home/edik/projects/eccjeu/input/andrea_input.csv | /home/edik/projects/eccjeu/output/com_db_comp/db_comp_metadata_manifest.csv | /home/edik/projects/eccjeu/output/com_legacy/download_case_manifest.csv
